Workbook
Name AfterRetirement: #REF!>=DesiredRetirementAge
Name AfterRetirement: #REF!>=DesiredRetirementAge
Name Age: IF(PlanYear<='Bảng khảo sát'!PlanYears,PlanYear-1+YourCurrentAge,NA())
Name Age: IF(PlanYear<=PlanYears,PlanYear-1+YourCurrentAge,NA())
Name AnnualPenionsBenefitsAtRetirement: #REF!
Name AnnualPensionBenefitAfterRetirementIncreasesPercentage: #REF!
Name AnnualPensionBenefitAmountUncertaintyPercentage: #REF!
Name AnnualPensionCenefitIncreasesUncertaintyPercentage: #REF!
Name AnnualSavingsAmountUncertaintyPercentage: #REF!
Name AnnualSavingsIncreasesUncertaintyPercentage: #REF!
Name Balance: IF(PlanYear<='Bảng khảo sát'!PlanYears,#REF!,NA())
Name Balance: IF(PlanYear<=PlanYears,#REF!,NA())
Name Balance_Over: IF(PlanYear<='Bảng khảo sát'!PlanYears,#REF!,NA())
Name Balance_Over: IF(PlanYear<=PlanYears,#REF!,NA())
Name Balance_Under: IF(PlanYear<='Bảng khảo sát'!PlanYears,#REF!,NA())
Name Balance_Under: IF(PlanYear<=PlanYears,#REF!,NA())
Name BeforeRetirement: #REF!<DesiredRetirementAge
Name BeforeRetirement: #REF!<DesiredRetirementAge
Name College: '[1]Mục tiêu bản thân'!#REF!
Name ColumnTitle1: #REF!
Name ColumnTitle2: #REF!
Name ColumnTitle3: #REF!
Name ColumnTitle4: #REF!
Name ColumnTitle5: #REF!
Name ColumnTitle6: #REF!
Name ColumnTitleRegion1..I114.1: #REF!
Name CurrentAnnualIncome: #REF!
Name CurrentAnnualIncomeIncreasesPercentage: #REF!
Name CurrentAnnualSavingsAmount: #REF!
Name CurrentAnnualSavingsAmount_Over: CurrentAnnualSavingsAmount+CurrentAnnualSavingsAmount*AnnualSavingsAmountUncertaintyPercentage/2
Name CurrentAnnualSavingsAmount_Over: CurrentAnnualSavingsAmount+CurrentAnnualSavingsAmount*AnnualSavingsAmountUncertaintyPercentage/2
Name CurrentAnnualSavingsAmount_Under: CurrentAnnualSavingsAmount-CurrentAnnualSavingsAmount*AnnualSavingsAmountUncertaintyPercentage/2
Name CurrentAnnualSavingsAmount_Under: CurrentAnnualSavingsAmount-CurrentAnnualSavingsAmount*AnnualSavingsAmountUncertaintyPercentage/2
Name CurrentAnnualSavingsIncreasesPercentage: #REF!
Name CurrentRetirementSavingsBalance: #REF!
Name DesiredRetirementAge: #REF!
Name DesiredRetirementIncome: IF(PlanYear<='Bảng khảo sát'!PlanYears,'Bảng khảo sát'!AfterRetirement*IncomeReplacementAtRetirementPercentage*CurrentAnnualIncome*(1+CurrentAnnualIncomeIncreasesPercentage)^(#REF!-#REF!),NA())
Name DesiredRetirementIncome: IF(PlanYear<=PlanYears,AfterRetirement*IncomeReplacementAtRetirementPercentage*CurrentAnnualIncome*(1+CurrentAnnualIncomeIncreasesPercentage)^(#REF!-#REF!),NA())
Name EndBalance: IF(PlanYear<='Bảng khảo sát'!PlanYears,#REF!+#REF!+#REF!-#REF!+#REF!,NA())
Name EndBalance: IF(PlanYear<=PlanYears,#REF!+#REF!+#REF!-#REF!+#REF!,NA())
Name IncomeReplacementAtRetirementPercentage: #REF!
Name Interest: IF(PlanYear<=PlanYears,(#REF!*BeforeRetirement*InvestmentReturnPreRetirementPercentage)+(#REF!*AfterRetirement*InvestmentReturnPostRetirementPercentage),NA())
Name InvestmentReturnPostRetirementPercentage: #REF!
Name InvestmentReturnPreRetirementPercentage: #REF!
Name InvestmentReturnUncertaintyPercentage: #REF!
Name IQ_CH: 110000
Name IQ_CQ: 5000
Name IQ_CY: 10000
Name IQ_DAILY: 500000
Name IQ_FH: 100000
Name IQ_FQ: 500
Name IQ_FY: 1000
Name IQ_LTM: 2000
Name IQ_MONTH: 15000
Name IQ_NTM: 6000
Name IQ_WEEK: 50000
Name IQ_YTD: 3000
Name LastRow: COUNTIF(#REF!,">1")+35
Name Months_in_term: #REF!
Name NET_MONTHLY_EXPENSES: #REF!

Sheet Từ khóa
E1: TỪ KHÓA
Q3: Đơn vị: triệu đồng
E5: Năm bắt đầu theo dõi | L5: ="Tuổi của bạn năm " &'Từ khóa'!E7 -> Tuổi của bạn năm 2023 | R5: Quy ước màu chữ:
S6: Màu xanh dương: Nhập dữ liệu
E7: 2023 | L7: 21 | S7: Màu đen: Kết quả trung gian
S8: Màu đỏ: Dữ liệu quan trọng
E10: Danh mục chi phí | L10: Danh mục thu nhập | R10: Kế hoạch phát triển | V10: Danh mục sản phẩm đầu tư
E11: # | F11: Khoản mục | L11: # | M11: Khoản mục | R11: # | S11: Khoản mục | V11: # | W11: Khoản mục | Z11: Mức sinh lời TB 5 năm | AC11: Rủi ro
E12: 1 | F12: Mua thực phẩm | L12: 1 | M12: Lương từ công ty | R12: 1 | S12: Mua sách | V12: 1 | W12: ETF - ETFVFM | Z12: 0.13 | AC12: 0.18
E13: 2 | F13: Mua đồ dùng trong nhà | L13: 2 | M13: Thu nhập khác | R13: 2 | S13: Khóa học ngắn hạn | V13: 2 | W13: ETF - ETFFINLEAD | Z13: 0.15 | AC13: 0.2
E14: 3 | F14: Đi ăn ở ngoài | L14: 3 | R14: 3 | S14: Khóa học dài hạn | V14: 3 | W14: DCBC | Z14: 0.16 | AC14: 0.2
E15: 4 | F15: Chi tiền phát triển bản thân | L15: 4 | R15: 4 | S15: Tham gia các buổi diễn thuyết | V15: 4 | W15: DCDS | Z15: 0.11 | AC15: 0.1
E16: 5 | F16: Chi tiền bảo hiểm | L16: 5 | R16: 5 | S16: Chi phát triển bản thân khác | V16: 5 | W16: DCBF | Z16: 0.09 | AC16: 0.08
E17: 6 | F17: Chi tiền điện, nước, internet, điện thoại, xăng xe | L17: 6 | R17: 6 | V17: 6 | W17: Trái phiếu Techcombank | Z17: 0.105 | AC17: 0.06
E18: 7 | F18: Chi tiền giải trí, quà tặng | L18: 7 | R18: 7 | V18: 7 | W18: Trái phiếu FE Credit | Z18: 0.1 | AC18: 0.08
E19: 8 | F19: Chi tiền cho con | L19: 8 | R19: 8 | V19: 8 | W19: Finhay | Z19: 0.06 | AC19: 0.07
E20: 9 | F20: Chi tiền trả nợ | R20: 9 | V20: 9 | W20: Bảo hiểm thuần túy | Z20: 0.04 | AC20: 0.05
E21: 10 | F21: Chi tiền cho tặng gia đình | R21: 10 | V21: 10 | W21: BH liên kết đầu tư | Z21: 0.12 | AC21: 0.05
E22: 11 | F22: Chi tiêu 1 | V22: 11 | W22: Tiền gửi ngân hàng | Z22: 0.05 | AC22: 0.02
E23: 12 | F23: Chi tiêu 2 | V23: 12 | W23: Cổ phiếu riêng lẻ | Z23: 0.12 | AC23: 0.06
E24: 13 | F24: Chi tiêu 3 | V24: 13 | W24: Sản phẩm 1 | Z24: 0 | AC24: 0
E25: 14 | F25: Chi tiêu 4 | V25: 14 | W25: Sản phẩm 2 | Z25: 0 | AC25: 0
E26: 15 | F26: Chi tiêu 5 | V26: 15 | W26: Sản phẩm 3 | Z26: 0 | AC26: 0

Sheet Dashboard
E1: THEO DÕI TÀI CHÍNH CÁ NHÂN
Q3: Đơn vị: triệu đồng
E6: ='Từ khóa'!E5 -> Năm bắt đầu theo dõi | F6: ='Từ khóa'!E7 -> 2023 | I6: Tổng tiết kiệm cần đạt | L6: =SUM('Mục tiêu bản thân'!$S$9:$T$18) -> 2850 | O6: Mức sinh lời trung bình ước tính | R6: ='Mục tiêu tài chính'!V251 -> 0.099677009
E26: ="Tổng thu nhập năm "&F6 -> Tổng thu nhập năm 2023 | F26: =Table2[[#Totals],[Tổng]] -> 329.4 | I26: ="Tổng chi tiêu năm "&F6 -> Tổng chi tiêu năm 2023 | L26: =Table3[[#Totals],[Tổng]] -> 223.75 | O26: ="Tiết kiệm năm "&F6 -> Tiết kiệm năm 2023 | R26: =F26-L26 -> 105.65
E64: Thu nhập | F64: Tháng 1 | G64: Tháng 2 | H64: Tháng 3 | I64: Tháng 4 | J64: Tháng 5 | K64: Tháng 6 | L64: Tháng 7 | M64: Tháng 8 | N64: Tháng 9 | O64: Tháng 10 | P64: Tháng 11 | Q64: Tháng 12 | R64: Tổng | S64: Xu hướng
E65: ='Từ khóa'!M12 -> Lương từ công ty | F65: ='T1'!W27 -> 20 | G65: ='T2'!W27 -> 25 | H65: ='T3'!W27 -> 18 | I65: ='T4'!W27 -> 19 | J65: ='T5'!W27 -> 20 | K65: ='T6'!W27 -> 18 | L65: ='T7'!W27 -> 18 | M65: ='T8'!W27 -> 18 | N65: ='T9'!W27 -> 20 | O65: ='T10'!W27 -> 20 | P65: ='T11'!W27 -> 19 | Q65: ='T12'!W27 -> 20 | R65: =SUM(F65:Q65) -> 235
E66: ='Từ khóa'!M13 -> Thu nhập khác | F66: ='T1'!W28 -> 4 | G66: ='T2'!W28 -> 4.5 | H66: ='T3'!W28 -> 5.7 | I66: ='T4'!W28 -> 4.9 | J66: ='T5'!W28 -> 12.8 | K66: ='T6'!W28 -> 9.5 | L66: ='T7'!W28 -> 11 | M66: ='T8'!W28 -> 7 | N66: ='T9'!W28 -> 7 | O66: ='T10'!W28 -> 8 | P66: ='T11'!W28 -> 5 | Q66: ='T12'!W28 -> 15 | R66: =SUM(F66:Q66) -> 94.4
E67: ='Từ khóa'!M14 -> 0 | F67: ='T1'!W29 -> 0 | G67: ='T2'!W29 -> 0 | H67: ='T3'!W29 -> 0 | I67: ='T4'!W29 -> 0 | J67: ='T5'!W29 -> 0 | K67: ='T6'!W29 -> 0 | L67: ='T7'!W29 -> 0 | M67: ='T8'!W29 -> 0 | N67: ='T9'!W29 -> 0 | O67: ='T10'!W29 -> 0 | P67: ='T11'!W29 -> 0 | Q67: ='T12'!W29 -> 0 | R67: =SUM(F67:Q67) -> 0
E68: ='Từ khóa'!M15 -> 0 | F68: ='T1'!W30 -> 0 | G68: ='T2'!W30 -> 0 | H68: ='T3'!W30 -> 0 | I68: ='T4'!W30 -> 0 | J68: ='T5'!W30 -> 0 | K68: ='T6'!W30 -> 0 | L68: ='T7'!W30 -> 0 | M68: ='T8'!W30 -> 0 | N68: ='T9'!W30 -> 0 | O68: ='T10'!W30 -> 0 | P68: ='T11'!W30 -> 0 | Q68: ='T12'!W30 -> 0 | R68: =SUM(F68:Q68) -> 0
E69: ='Từ khóa'!M16 -> 0 | F69: ='T1'!W31 -> 0 | G69: ='T2'!W31 -> 0 | H69: ='T3'!W31 -> 0 | I69: ='T4'!W31 -> 0 | J69: ='T5'!W31 -> 0 | K69: ='T6'!W31 -> 0 | L69: ='T7'!W31 -> 0 | M69: ='T8'!W31 -> 0 | N69: ='T9'!W31 -> 0 | O69: ='T10'!W31 -> 0 | P69: ='T11'!W31 -> 0 | Q69: ='T12'!W31 -> 0 | R69: =SUM(F69:Q69) -> 0
E70: ='Từ khóa'!M17 -> 0 | F70: ='T1'!W32 -> 0 | G70: ='T2'!W32 -> 0 | H70: ='T3'!W32 -> 0 | I70: ='T4'!W32 -> 0 | J70: ='T5'!W32 -> 0 | K70: ='T6'!W32 -> 0 | L70: ='T7'!W32 -> 0 | M70: ='T8'!W32 -> 0 | N70: ='T9'!W32 -> 0 | O70: ='T10'!W32 -> 0 | P70: ='T11'!W32 -> 0 | Q70: ='T12'!W32 -> 0 | R70: =SUM(F70:Q70) -> 0
E71: ='Từ khóa'!M18 -> 0 | F71: ='T1'!W33 -> 0 | G71: ='T2'!W33 -> 0 | H71: ='T3'!W33 -> 0 | I71: ='T4'!W33 -> 0 | J71: ='T5'!W33 -> 0 | K71: ='T6'!W33 -> 0 | L71: ='T7'!W33 -> 0 | M71: ='T8'!W33 -> 0 | N71: ='T9'!W33 -> 0 | O71: ='T10'!W33 -> 0 | P71: ='T11'!W33 -> 0 | Q71: ='T12'!W33 -> 0 | R71: =SUM(F71:Q71) -> 0
E72: ='Từ khóa'!M19 -> 0 | F72: ='T1'!W34 -> 0 | G72: ='T2'!W34 -> 0 | H72: ='T3'!W34 -> 0 | I72: ='T4'!W34 -> 0 | J72: ='T5'!W34 -> 0 | K72: ='T6'!W34 -> 0 | L72: ='T7'!W34 -> 0 | M72: ='T8'!W34 -> 0 | N72: ='T9'!W34 -> 0 | O72: ='T10'!W34 -> 0 | P72: ='T11'!W34 -> 0 | Q72: ='T12'!W34 -> 0 | R72: =SUM(F72:Q72) -> 0
E73: Tổng thu nhập | F73: =SUBTOTAL(109,Table2[Tháng 1]) -> 24 | G73: =SUBTOTAL(109,Table2[Tháng 2]) -> 29.5 | H73: =SUBTOTAL(109,Table2[Tháng 3]) -> 23.7 | I73: =SUBTOTAL(109,Table2[Tháng 4]) -> 23.9 | J73: =SUBTOTAL(109,Table2[Tháng 5]) -> 32.8 | K73: =SUBTOTAL(109,Table2[Tháng 6]) -> 27.5 | L73: =SUBTOTAL(109,Table2[Tháng 7]) -> 29 | M73: =SUBTOTAL(109,Table2[Tháng 8]) -> 25 | N73: =SUBTOTAL(109,Table2[Tháng 9]) -> 27 | O73: =SUBTOTAL(109,Table2[Tháng 10]) -> 28 | P73: =SUBTOTAL(109,Table2[Tháng 11]) -> 24 | Q73: =SUBTOTAL(109,Table2[Tháng 12]) -> 35 | R73: =SUBTOTAL(109,Table2[Tổng]) -> 329.4
E75: Chi tiêu | F75: Tháng 1 | G75: Tháng 2 | H75: Tháng 3 | I75: Tháng 4 | J75: Tháng 5 | K75: Tháng 6 | L75: Tháng 7 | M75: Tháng 8 | N75: Tháng 9 | O75: Tháng 10 | P75: Tháng 11 | Q75: Tháng 12 | R75: Tổng | S75: Xu hướng
E76: ='Từ khóa'!F12 -> Mua thực phẩm | F76: ='T1'!W42 -> 5.5 | G76: ='T2'!W42 -> 5 | H76: ='T3'!W42 -> 6.8 | I76: ='T4'!W42 -> 5 | J76: ='T5'!W42 -> 3.4 | K76: ='T6'!W42 -> 4.3 | L76: ='T7'!W42 -> 5.5 | M76: ='T8'!W42 -> 7 | N76: ='T9'!W42 -> 4.2 | O76: ='T10'!W42 -> 5 | P76: ='T11'!W42 -> 5 | Q76: ='T12'!W42 -> 5 | R76: =SUM(F76:Q76) -> 61.7
E77: ='Từ khóa'!F13 -> Mua đồ dùng trong nhà | F77: ='T1'!W43 -> 0.3 | G77: ='T2'!W43 -> 0.7 | H77: ='T3'!W43 -> 1.1 | I77: ='T4'!W43 -> 0.4 | J77: ='T5'!W43 -> 1 | K77: ='T6'!W43 -> 0.3 | L77: ='T7'!W43 -> 2.5 | M77: ='T8'!W43 -> 1.3 | N77: ='T9'!W43 -> 1.3 | O77: ='T10'!W43 -> 1.1 | P77: ='T11'!W43 -> 0.4 | Q77: ='T12'!W43 -> 4.5 | R77: =SUM(F77:Q77) -> 14.9
E78: ='Từ khóa'!F14 -> Đi ăn ở ngoài | F78: ='T1'!W44 -> 0.8 | G78: ='T2'!W44 -> 1.8 | H78: ='T3'!W44 -> 0.5 | I78: ='T4'!W44 -> 1.3 | J78: ='T5'!W44 -> 1.3 | K78: ='T6'!W44 -> 1 | L78: ='T7'!W44 -> 0.5 | M78: ='T8'!W44 -> 0 | N78: ='T9'!W44 -> 1 | O78: ='T10'!W44 -> 1.9 | P78: ='T11'!W44 -> 2.5 | Q78: ='T12'!W44 -> 3 | R78: =SUM(F78:Q78) -> 15.6
E79: ='Từ khóa'!F15 -> Chi tiền phát triển bản thân | F79: ='T1'!W45 -> 1.1 | G79: ='T2'!W45 -> 2.3 | H79: ='T3'!W45 -> 1.5 | I79: ='T4'!W45 -> 1.3 | J79: ='T5'!W45 -> 2 | K79: ='T6'!W45 -> 1.1 | L79: ='T7'!W45 -> 1.1 | M79: ='T8'!W45 -> 3.1 | N79: ='T9'!W45 -> 0.8 | O79: ='T10'!W45 -> 2.1 | P79: ='T11'!W45 -> 1.5 | Q79: ='T12'!W45 -> 2 | R79: =SUM(F79:Q79) -> 19.9
E80: ='Từ khóa'!F16 -> Chi tiền bảo hiểm | F80: ='T1'!W46 -> 0 | G80: ='T2'!W46 -> 0 | H80: ='T3'!W46 -> 0.5 | I80: ='T4'!W46 -> 0 | J80: ='T5'!W46 -> 0 | K80: ='T6'!W46 -> 0 | L80: ='T7'!W46 -> 0 | M80: ='T8'!W46 -> 0 | N80: ='T9'!W46 -> 0 | O80: ='T10'!W46 -> 0 | P80: ='T11'!W46 -> 0 | Q80: ='T12'!W46 -> 0 | R80: =SUM(F80:Q80) -> 0.5
E81: ='Từ khóa'!F17 -> Chi tiền điện, nước, internet, điện thoại, xăng xe | F81: ='T1'!W47 -> 1.3 | G81: ='T2'!W47 -> 1.6 | H81: ='T3'!W47 -> 1.65 | I81: ='T4'!W47 -> 1.35 | J81: ='T5'!W47 -> 1.5 | K81: ='T6'!W47 -> 1.75 | L81: ='T7'!W47 -> 1.05 | M81: ='T8'!W47 -> 2.65 | N81: ='T9'!W47 -> 2.55 | O81: ='T10'!W47 -> 1.35 | P81: ='T11'!W47 -> 1.35 | Q81: ='T12'!W47 -> 1.55 | R81: =SUM(F81:Q81) -> 19.65
E82: ='Từ khóa'!F18 -> Chi tiền giải trí, quà tặng | F82: ='T1'!W48 -> 0 | G82: ='T2'!W48 -> 0 | H82: ='T3'!W48 -> 0.7 | I82: ='T4'!W48 -> 0 | J82: ='T5'!W48 -> 0.4 | K82: ='T6'!W48 -> 0 | L82: ='T7'!W48 -> 0 | M82: ='T8'!W48 -> 0.5 | N82: ='T9'!W48 -> 0.3 | O82: ='T10'!W48 -> 0 | P82: ='T11'!W48 -> 0.5 | Q82: ='T12'!W48 -> 2.5 | R82: =SUM(F82:Q82) -> 4.9
E83: ='Từ khóa'!F19 -> Chi tiền cho con | F83: ='T1'!W49 -> 0 | G83: ='T2'!W49 -> 0 | H83: ='T3'!W49 -> 0 | I83: ='T4'!W49 -> 0 | J83: ='T5'!W49 -> 0 | K83: ='T6'!W49 -> 0 | L83: ='T7'!W49 -> 1 | M83: ='T8'!W49 -> 1 | N83: ='T9'!W49 -> 0.3 | O83: ='T10'!W49 -> 0 | P83: ='T11'!W49 -> 0 | Q83: ='T12'!W49 -> 0 | R83: =SUM(F83:Q83) -> 2.3
E84: ='Từ khóa'!F20 -> Chi tiền trả nợ | F84: ='T1'!W50 -> 6.5 | G84: ='T2'!W50 -> 6.5 | H84: ='T3'!W50 -> 6.5 | I84: ='T4'!W50 -> 6.5 | J84: ='T5'!W50 -> 6.5 | K84: ='T6'!W50 -> 6.5 | L84: ='T7'!W50 -> 6.5 | M84: ='T8'!W50 -> 6.5 | N84: ='T9'!W50 -> 6.5 | O84: ='T10'!W50 -> 6.5 | P84: ='T11'!W50 -> 6.5 | Q84: ='T12'!W50 -> 6.5 | R84: =SUM(F84:Q84) -> 78
E85: ='Từ khóa'!F21 -> Chi tiền cho tặng gia đình | F85: ='T1'!W51 -> 2 | G85: ='T2'!W51 -> 1.3 | H85: ='T3'!W51 -> 0 | I85: ='T4'!W51 -> 1.4 | J85: ='T5'!W51 -> 0.5 | K85: ='T6'!W51 -> 0 | L85: ='T7'!W51 -> 0.1 | M85: ='T8'!W51 -> 0.5 | N85: ='T9'!W51 -> 0.5 | O85: ='T10'!W51 -> 0 | P85: ='T11'!W51 -> 0 | Q85: ='T12'!W51 -> 0 | R85: =SUM(F85:Q85) -> 6.3
E86: ='Từ khóa'!F22 -> Chi tiêu 1 | F86: ='T1'!W52 -> 0 | G86: ='T2'!W52 -> 0 | H86: ='T3'!W52 -> 0 | I86: ='T4'!W52 -> 0 | J86: ='T5'!W52 -> 0 | K86: ='T6'!W52 -> 0 | L86: ='T7'!W52 -> 0 | M86: ='T8'!W52 -> 0 | N86: ='T9'!W52 -> 0 | O86: ='T10'!W52 -> 0 | P86: ='T11'!W52 -> 0 | Q86: ='T12'!W52 -> 0 | R86: =SUM(F86:Q86) -> 0
E87: ='Từ khóa'!F23 -> Chi tiêu 2 | F87: ='T1'!W53 -> 0 | G87: ='T2'!W53 -> 0 | H87: ='T3'!W53 -> 0 | I87: ='T4'!W53 -> 0 | J87: ='T5'!W53 -> 0 | K87: ='T6'!W53 -> 0 | L87: ='T7'!W53 -> 0 | M87: ='T8'!W53 -> 0 | N87: ='T9'!W53 -> 0 | O87: ='T10'!W53 -> 0 | P87: ='T11'!W53 -> 0 | Q87: ='T12'!W53 -> 0 | R87: =SUM(F87:Q87) -> 0
... E90: ='Từ khóa'!F26 -> Chi tiêu 5 | F90: ='T1'!W56 -> 0 | G90: ='T2'!W56 -> 0 | H90: ='T3'!W56 -> 0 | I90: ='T4'!W56 -> 0 | J90: ='T5'!W56 -> 0 | K90: ='T6'!W56 -> 0 | L90: ='T7'!W56 -> 0 | M90: ='T8'!W56 -> 0 | N90: ='T9'!W56 -> 0 | O90: ='T10'!W56 -> 0 | P90: ='T11'!W56 -> 0 | Q90: ='T12'!W56 -> 0 | R90: =SUM(F90:Q90) -> 0
E91: Tổng chi tiêu | F91: =SUBTOTAL(109,Table3[Tháng 1]) -> 17.5 | G91: =SUBTOTAL(109,Table3[Tháng 2]) -> 19.2 | H91: =SUBTOTAL(109,Table3[Tháng 3]) -> 19.25 | I91: =SUBTOTAL(109,Table3[Tháng 4]) -> 17.25 | J91: =SUBTOTAL(109,Table3[Tháng 5]) -> 16.6 | K91: =SUBTOTAL(109,Table3[Tháng 6]) -> 14.95 | L91: =SUBTOTAL(109,Table3[Tháng 7]) -> 18.25 | M91: =SUBTOTAL(109,Table3[Tháng 8]) -> 22.55 | N91: =SUBTOTAL(109,Table3[Tháng 9]) -> 17.45 | O91: =SUBTOTAL(109,Table3[Tháng 10]) -> 17.95 | P91: =SUBTOTAL(109,Table3[Tháng 11]) -> 17.75 | Q91: =SUBTOTAL(109,Table3[Tháng 12]) -> 25.05 | R91: =SUBTOTAL(109,Table3[Tổng]) -> 223.75
E92: Kế hoạch chi tiêu | F92: ='Kế hoạch thu nhập và chi tiêu'!$L$41 -> 18.5 | G92: ='Kế hoạch thu nhập và chi tiêu'!$L$41 -> 18.5 | H92: ='Kế hoạch thu nhập và chi tiêu'!$L$41 -> 18.5 | I92: ='Kế hoạch thu nhập và chi tiêu'!$L$41 -> 18.5 | J92: ='Kế hoạch thu nhập và chi tiêu'!$L$41 -> 18.5 | K92: ='Kế hoạch thu nhập và chi tiêu'!$L$41 -> 18.5 | L92: ='Kế hoạch thu nhập và chi tiêu'!$L$41 -> 18.5 | M92: ='Kế hoạch thu nhập và chi tiêu'!$L$41 -> 18.5 | ... Q92: ='Kế hoạch thu nhập và chi tiêu'!$L$41 -> 18.5
E93: Lũy kế chênh lệch | F93: =F92-Table3[[#Totals],[Tháng 1]] -> 1 | G93: =F93+G92-Table3[[#Totals],[Tháng 2]] -> 0.3 | H93: =G93+H92-Table3[[#Totals],[Tháng 3]] -> -0.45 | I93: =H93+I92-Table3[[#Totals],[Tháng 4]] -> 0.8 | J93: =I93+J92-Table3[[#Totals],[Tháng 5]] -> 2.7 | K93: =J93+K92-Table3[[#Totals],[Tháng 6]] -> 6.25 | L93: =K93+L92-Table3[[#Totals],[Tháng 7]] -> 6.5 | M93: =L93+M92-Table3[[#Totals],[Tháng 8]] -> 2.45 | N93: =M93+N92-Table3[[#Totals],[Tháng 9]] -> 3.5 | O93: =N93+O92-Table3[[#Totals],[Tháng 10]] -> 4.05 | P93: =O93+P92-Table3[[#Totals],[Tháng 11]] -> 4.8 | Q93: =P93+Q92-Table3[[#Totals],[Tháng 12]] -> -1.75
E95: Tiết kiệm | F95: Tháng 1 | G95: Tháng 2 | H95: Tháng 3 | I95: Tháng 4 | J95: Tháng 5 | K95: Tháng 6 | L95: Tháng 7 | M95: Tháng 8 | N95: Tháng 9 | O95: Tháng 10 | P95: Tháng 11 | Q95: Tháng 12 | R95: Tổng | S95: Xu hướng
E96: Giá trị | F96: =Table2[[#Totals],[Tháng 1]]-Table3[[#Totals],[Tháng 1]] -> 6.5 | G96: =Table2[[#Totals],[Tháng 2]]-Table3[[#Totals],[Tháng 2]] -> 10.3 | H96: =Table2[[#Totals],[Tháng 3]]-Table3[[#Totals],[Tháng 3]] -> 4.45 | I96: =Table2[[#Totals],[Tháng 4]]-Table3[[#Totals],[Tháng 4]] -> 6.65 | J96: =Table2[[#Totals],[Tháng 5]]-Table3[[#Totals],[Tháng 5]] -> 16.2 | K96: =Table2[[#Totals],[Tháng 6]]-Table3[[#Totals],[Tháng 6]] -> 12.55 | L96: =Table2[[#Totals],[Tháng 7]]-Table3[[#Totals],[Tháng 7]] -> 10.75 | M96: =Table2[[#Totals],[Tháng 8]]-Table3[[#Totals],[Tháng 8]] -> 2.45 | N96: =Table2[[#Totals],[Tháng 9]]-Table3[[#Totals],[Tháng 9]] -> 9.55 | O96: =Table2[[#Totals],[Tháng 10]]-Table3[[#Totals],[Tháng 10]] -> 10.05 | P96: =Table2[[#Totals],[Tháng 11]]-Table3[[#Totals],[Tháng 11]] -> 6.25 | Q96: =Table2[[#Totals],[Tháng 12]]-Table3[[#Totals],[Tháng 12]] -> 9.95 | R96: =SUM(F96:Q96) -> 105.65
E98: Chi phí phát triển bản thân | F98: Tháng 1 | G98: Tháng 2 | H98: Tháng 3 | I98: Tháng 4 | J98: Tháng 5 | K98: Tháng 6 | L98: Tháng 7 | M98: Tháng 8 | N98: Tháng 9 | O98: Tháng 10 | P98: Tháng 11 | Q98: Tháng 12 | R98: Tổng | S98: Xu hướng
E99: ='Từ khóa'!S12 -> Mua sách | F99: ='T1'!AE92 -> 0.1 | G99: ='T2'!AE92 -> 0.5 | H99: ='T3'!AE92 -> 0.3 | I99: ='T4'!AE92 -> 0.1 | J99: ='T5'!AE92 -> 0.3 | K99: ='T6'!AE92 -> 0.1 | L99: ='T7'!AE92 -> 0.5 | M99: ='T8'!AE92 -> 0.5 | N99: ='T9'!AE92 -> 0.5 | O99: ='T10'!AE92 -> 1 | P99: ='T11'!AE92 -> 0.5 | Q99: ='T12'!AE92 -> 0.5 | R99: =SUM(F99:Q99) -> 4.9
E100: ='Từ khóa'!S13 -> Khóa học ngắn hạn | F100: ='T1'!AE93 -> 1 | G100: ='T2'!AE93 -> 1 | H100: ='T3'!AE93 -> 1.2 | I100: ='T4'!AE93 -> 1.2 | J100: ='T5'!AE93 -> 1.7 | K100: ='T6'!AE93 -> 1 | L100: ='T7'!AE93 -> 0.6 | M100: ='T8'!AE93 -> 2.6 | N100: ='T9'!AE93 -> 0.3 | O100: ='T10'!AE93 -> 1.1 | P100: ='T11'!AE93 -> 1 | Q100: ='T12'!AE93 -> 1 | R100: =SUM(F100:Q100) -> 13.7
E101: ='Từ khóa'!S14 -> Khóa học dài hạn | F101: ='T1'!AE94 -> 0 | G101: ='T2'!AE94 -> 0 | H101: ='T3'!AE94 -> 0 | I101: ='T4'!AE94 -> 0 | J101: ='T5'!AE94 -> 0 | K101: ='T6'!AE94 -> 0 | L101: ='T7'!AE94 -> 0 | M101: ='T8'!AE94 -> 0 | N101: ='T9'!AE94 -> 0 | O101: ='T10'!AE94 -> 0 | P101: ='T11'!AE94 -> 0 | Q101: ='T12'!AE94 -> 0 | R101: =SUM(F101:Q101) -> 0
E102: ='Từ khóa'!#REF! -> #REF! | F102: ='T1'!AE95 -> 0 | G102: ='T2'!AE95 -> 0 | H102: ='T3'!AE95 -> 0 | I102: ='T4'!AE95 -> 0 | J102: ='T5'!AE95 -> 0 | K102: ='T6'!AE95 -> 0 | L102: ='T7'!AE95 -> 0 | M102: ='T8'!AE95 -> 0 | N102: ='T9'!AE95 -> 0 | O102: ='T10'!AE95 -> 0 | P102: ='T11'!AE95 -> 0 | Q102: ='T12'!AE95 -> 0 | R102: =SUM(F102:Q102) -> 0
E103: ='Từ khóa'!S15 -> Tham gia các buổi diễn thuyết | F103: ='T1'!AE96 -> 0 | G103: ='T2'!AE96 -> 0 | H103: ='T3'!AE96 -> 0 | I103: ='T4'!AE96 -> 0 | J103: ='T5'!AE96 -> 0 | K103: ='T6'!AE96 -> 0 | L103: ='T7'!AE96 -> 0 | M103: ='T8'!AE96 -> 0 | N103: ='T9'!AE96 -> 0 | O103: ='T10'!AE96 -> 0 | P103: ='T11'!AE96 -> 0 | Q103: ='T12'!AE96 -> 0 | R103: =SUM(F103:Q103) -> 0
E104: ='Từ khóa'!S16 -> Chi phát triển bản thân khác | F104: ='T1'!AE97 -> 0 | G104: ='T2'!AE97 -> 0.8 | H104: ='T3'!AE97 -> 0 | I104: ='T4'!AE97 -> 0 | J104: ='T5'!AE97 -> 0 | K104: ='T6'!AE97 -> 0 | L104: ='T7'!AE97 -> 0 | M104: ='T8'!AE97 -> 0 | N104: ='T9'!AE97 -> 0 | O104: ='T10'!AE97 -> 0 | P104: ='T11'!AE97 -> 0 | Q104: ='T12'!AE97 -> 0 | R104: =SUM(F104:Q104) -> 0.8
...

Sheet Mục tiêu bản thân
E1: XÁC ĐỊNH MỤC TIÊU BẢN THÂN
P4: Đơn vị: triệu đồng
I5: Thời điểm | K5: Nội dung
E6: Xác định đích đến cuộc sống | I6: 50 | K6: Từng bước đạt mục tiêu tài chính trong tương lai
I8: Mục tiêu trả nợ | K8: Thời điểm (tuổi) | M8: Nội dung | S8: Giá trị
E9: Xác định các khoản nợ tài chính | I9: 1 | K9: 35 | M9: Vay mua chung cư | S9: 500
I10: 2
I11: 3
I13: Mục tiêu đầu tư | K13: Thời điểm (tuổi) | M13: Nội dung | S13: Giá trị
E14: Xác định mục tiêu tài chính | I14: 4 | K14: 25 | M14: Du lịch xuyên Thái Lan | S14: 50
I15: 5 | K15: 26 | M15: Quỹ dự phòng tài chính | S15: 100
I16: 6 | K16: 28 | M16: Đám cưới | S16: 200
I17: 7 | K17: 30 | M17: Khởi nghiệp | S17: 500
I18: 8 | K18: 38 | M18: Mua chung cư | S18: 1500
I19: 9 | K19: 46 | M19: Cho con đi học đại học | S19: 500
I20: 10 | K20: 50 | M20: Hưu trí | S20: 500
I23: Giá trị
E24: Tỷ lệ tiết kiệm mục tiêu | I24: 0.4
I27: Nội dung
E28: Định vị giá trị bản thân | I28: Sẵn sàng học hỏi cái mới
I29: Nhiệt huyết trong công việc
I34: Nội dung
E35: Phân tích hoàn cảnh gia đình | I35: Ba mẹ có hỗ trợ mua chung cư , lo đám cưới
I41: Nội dung
E42: Phân tích về môi trường làm việc | I42: Môi trường đa quốc gia, có nhiều cơ hội phát triển
I43: Môi trường làm việc có sự cạnh tranh gay gắt, áp lực KPI
I44: Có chế độ đãi ngộ tốt về lương thưởng, lương bổng
I48: Kết quả
E49: Khảo sát khả năng chịu đựng rủi ro | I49: Link khảo sát | K49: ='Bảng khảo sát'!A59 -> Kết quả khảo sát khả năng chịu đựng rủi ro: Bạn là người trung lập với rủi ro, bạn nên duy trì các tài sản rủi ro tại mức trung bình
E52: Khảo sát hoàn cảnh | I52: Link khảo sát | K52: ='Bảng khảo sát'!A126 -> Kết quả khảo sát hoàn cảnh: Bạn trong điều kiện bình thường để phát triển tài chính của bạn trong dài hạn

Sheet Mục tiêu tài chính
E1: XÁC ĐỊNH MỤC TIÊU TÀI CHÍNH
Q3: Đơn vị: triệu đồng
F4: Phần 1 | H4: Phần 2 | N4: ='Từ khóa'!L5 -> Tuổi của bạn năm 2023 | Q4: ='Từ khóa'!L7 -> 21
E5: Phần 1: Thanh toán các khoản nợ và xây dựng mục tiêu tài chính
E8: THANH TOÁN CÁC KHOẢN NỢ
E9: ='Mục tiêu bản thân'!I8&" "&'Mục tiêu bản thân'!I9&": "&'Mục tiêu bản thân'!M9 -> Mục tiêu trả nợ 1: Vay mua chung cư
E11: Năm bắt đầu | I11: 2037 | K11: Tóm tắt kế hoạch
E12: Năm kết thúc | I12: 2052 | K12: Khoản mục | O12: Giá trị
E13: Giá trị khoản nợ | I13: ='Mục tiêu bản thân'!S9 -> 500
E14: Lãi suất vay (năm) | I14: 0.08 | K14: Thời gian trả nợ còn lại (năm) | O14: =IF(I12-I11>-0.1,I12-I11+1,0) -> 16
E15: Số tiền nợ đã thanh toán trước đó | I15: 400 | K15: Số tiền thanh toán hàng tháng | O15: =IF(O14=0,0,-PMT(I14/12,O14*12,I16)) -> 0.92492503
E16: Mục tiêu thanh toán hiện tại | I16: =I13-I15 -> 100 | K16: Số tiền thanh toán hàng năm | O16: =O15*12 -> 11.0991
E18: ='Mục tiêu bản thân'!I8&" "&'Mục tiêu bản thân'!I10&": "&'Mục tiêu bản thân'!M10 -> Mục tiêu trả nợ 2:
E20: Năm bắt đầu | K20: Tóm tắt kế hoạch
E21: Năm kết thúc | K21: Khoản mục | O21: Giá trị
E22: Giá trị khoản nợ | I22: ='Mục tiêu bản thân'!S10 -> 0
E23: Lãi suất vay (năm) | K23: Thời gian trả nợ còn lại (năm) | O23: =IF(I21-I20>-0.1,I21-I20+1,0) -> 1
E24: Số tiền nợ đã thanh toán trước đó | K24: Số tiền thanh toán hàng tháng | O24: =IF(O23=0,0,-PMT(I23/12,O23*12,I24,I25)) -> 0
E25: Mục tiêu tiết kiệm cần đạt | I25: =I22-I24 -> 0 | K25: Số tiền thanh toán hàng năm | O25: =O24*12 -> 0
E27: ='Mục tiêu bản thân'!I8&" "&'Mục tiêu bản thân'!I11&": "&'Mục tiêu bản thân'!M11 -> Mục tiêu trả nợ 3:
E29: Năm bắt đầu | K29: Tóm tắt kế hoạch
E30: Năm kết thúc | K30: Khoản mục | O30: Giá trị
E31: Giá trị khoản nợ | I31: ='Mục tiêu bản thân'!S11 -> 0
E32: Lãi suất vay (năm) | K32: Thời gian trả nợ còn lại (năm) | O32: =IF(I30-I29>-0.1,I30-I29+1,0) -> 1
E33: Số tiền nợ đã thanh toán trước đó | K33: Số tiền thanh toán hàng tháng | O33: =IF(O32=0,0,-PMT(I32/12,O32*12,I33,I34)) -> 0
E34: Mục tiêu tiết kiệm cần đạt | I34: =I31-I33 -> 0 | K34: Số tiền thanh toán hàng năm | O34: =O33*12 -> 0
E36: XÂY DỰNG MỤC TIÊU TÀI CHÍNH
E37: ='Mục tiêu bản thân'!I13&" "&'Mục tiêu bản thân'!I14&": "&'Mục tiêu bản thân'!M14 -> Mục tiêu đầu tư 4: Du lịch xuyên Thái Lan
E39: Năm bắt đầu | I39: 2023 | K39: Tóm tắt kế hoạch | P39: Sản phẩm đầu tư
E40: Năm kết thúc | I40: 2026 | K40: Khoản mục | O40: Giá trị | R40: Loại sản phẩm | U40: Tỷ trọng | V40: Lợi nhuận | W40: Rủi ro
E41: Giá trị | I41: ='Mục tiêu bản thân'!S14 -> 50 | P41: Sản phẩm 1 | R41: Tiền gửi ngân hàng | U41: 0.5 | V41: =SUMIF('Từ khóa'!$W$12:$Y$26,R41,'Từ khóa'!$Z$12:$AB$26) -> 0.05 | W41: =SUMIF('Từ khóa'!$W$12:$Y$26,R41,'Từ khóa'!$AC$12:$AC$26) -> 0.02
E42: LS tiết kiệm/đầu tư ước tính (năm) | I42: =U44 -> 0.0865 | K42: Thời gian tiết kiệm (năm) | O42: =IF(I40-I39>-0.1,I40-I39+1,0) -> 4 | P42: Sản phẩm 2 | R42: ETF - ETFFINLEAD | U42: 0.2 | V42: =SUMIF('Từ khóa'!$W$12:$Y$26,R42,'Từ khóa'!$Z$12:$AB$26) -> 0.15 | W42: =SUMIF('Từ khóa'!$W$12:$Y$26,R42,'Từ khóa'!$AC$12:$AC$26) -> 0.2
E43: Số tiền tích lũy hiện có | I43: 0 | K43: Số tiền thanh toán hàng tháng | O43: =IF(O42=0,0,-PMT(I42/12,O42*12,I43,I44)) -> 0.87554246 | P43: Sản phẩm 3 | R43: Trái phiếu Techcombank | U43: 0.3 | V43: =SUMIF('Từ khóa'!$W$12:$Y$26,R43,'Từ khóa'!$Z$12:$AB$26) -> 0.105 | W43: =SUMIF('Từ khóa'!$W$12:$Y$26,R43,'Từ khóa'!$AC$12:$AC$26) -> 0.06
E44: Mục tiêu tiết kiệm cần đạt | I44: =I41-I43 -> 50 | K44: Số tiền thanh toán hàng năm | O44: =O43*12 -> 10.50651 | P44: Mức sinh lời kỳ vọng trung bình | U44: =IFERROR(SUMPRODUCT(U41:U43,V41:V43),IFERROR(SUMPRODUCT(U41:U42,V41:V42),V41)) -> 0.0865
E46: ='Mục tiêu bản thân'!I13&" "&'Mục tiêu bản thân'!I15&": "&'Mục tiêu bản thân'!M15 -> Mục tiêu đầu tư 5: Quỹ dự phòng tài chính
E48: Năm bắt đầu | I48: 2023 | K48: Tóm tắt kế hoạch | P48: Sản phẩm đầu tư
E49: Năm kết thúc | I49: 2026 | K49: Khoản mục | O49: Giá trị | R49: Loại sản phẩm | U49: Tỷ trọng | V49: Lợi nhuận | W49: Rủi ro
E50: Giá trị | I50: ='Mục tiêu bản thân'!S15 -> 100 | P50: Sản phẩm 1 | R50: Trái phiếu Techcombank | U50: 1 | V50: =SUMIF('Từ khóa'!$W$12:$Y$26,R50,'Từ khóa'!$Z$12:$AB$26) -> 0.105 | W50: =SUMIF('Từ khóa'!$W$12:$Y$26,R50,'Từ khóa'!$AC$12:$AC$26) -> 0.06
E51: LS tiết kiệm/đầu tư ước tính (năm) | I51: =U53 -> 0.105 | K51: Thời gian tiết kiệm (năm) | O51: =IF(I49-I48>-0.1,I49-I48+1,0) -> 4 | P51: Sản phẩm 2 | U51: 0 | V51: =SUMIF('Từ khóa'!$W$12:$Y$26,R51,'Từ khóa'!$Z$12:$AB$26) -> 0 | W51: =SUMIF('Từ khóa'!$W$12:$Y$26,R51,'Từ khóa'!$AC$12:$AC$26) -> 0
E52: Số tiền tích lũy hiện có | I52: 0 | K52: Số tiền thanh toán hàng tháng | O52: =IF(O51=0,0,-PMT(I51/12,O51*12,I52,I53)) -> 1.685338 | P52: Sản phẩm 3 | U52: 0 | V52: =SUMIF('Từ khóa'!$W$12:$Y$26,R52,'Từ khóa'!$Z$12:$AB$26) -> 0 | W52: =SUMIF('Từ khóa'!$W$12:$Y$26,R52,'Từ khóa'!$AC$12:$AC$26) -> 0
...

Sheet Cân đối lộ trình nghề nghiệp
E1: CÂN ĐỐI LỘ TRÌNH NGHỀ NGHIỆP
M3: Đơn vị: triệu đồng
F4: Phần 1 | G4: Phần 2 | K4: Quy ước: Tuổi bắt đầu có thu nhập là 22 tuổi
E19: Phần 1: Lộ trình tài chính cá nhân tổng thể
E22: Tuổi | F22: Thu nhập cần có | G22: Công cụ | O22: Mức sinh lời cần thiết | Q22: Kỹ năng cần thiết
G23: Cổ phiếu | I23: Trái phiếu | K23: Bảo hiểm | M23: Tiền gửi
E24: ='Từ khóa'!L7 -> 21 | F24: =SUMIF('Mục tiêu tài chính'!$F$107:$F$145,'Cân đối lộ trình nghề nghiệp'!E24,'Mục tiêu tài chính'!$AB$107:$AC$145) -> 6.4022011 | G24: =SUMIF('Mục tiêu tài chính'!$X$221:$X$250,'Cân đối lộ trình nghề nghiệp'!E24,'Mục tiêu tài chính'!$Y$221:$Y$250) -> 0.2356735 | I24: =SUMIF('Mục tiêu tài chính'!$X$221:$X$250,'Cân đối lộ trình nghề nghiệp'!E24,'Mục tiêu tài chính'!$Z$221:$Z$250) -> 0.34543072 | K24: =SUMIF('Mục tiêu tài chính'!$X$221:$X$250,'Cân đối lộ trình nghề nghiệp'!E24,'Mục tiêu tài chính'!$AA$221:$AA$250) -> 0.085081082 | M24: =SUMIF('Mục tiêu tài chính'!$X$221:$X$250,'Cân đối lộ trình nghề nghiệp'!E24,'Mục tiêu tài chính'!$AB$221:$AB$250) -> 0.3338147 | O24: =SUMIF('Mục tiêu tài chính'!$X$221:$X$250,'Cân đối lộ trình nghề nghiệp'!E24,'Mục tiêu tài chính'!$V$221:$V$250) -> 0.089433417 | Q24: Kỹ năng làm việc nhóm
E25: =E24+5 -> 26 | F25: =SUMIF('Mục tiêu tài chính'!$F$107:$F$145,'Cân đối lộ trình nghề nghiệp'!E25,'Mục tiêu tài chính'!$AB$107:$AC$145) -> 28.502823 | G25: =SUMIF('Mục tiêu tài chính'!$X$221:$X$250,'Cân đối lộ trình nghề nghiệp'!E25,'Mục tiêu tài chính'!$Y$221:$Y$250) -> 0.56757058 | I25: =SUMIF('Mục tiêu tài chính'!$X$221:$X$250,'Cân đối lộ trình nghề nghiệp'!E25,'Mục tiêu tài chính'!$Z$221:$Z$250) -> 0.20568591 | K25: =SUMIF('Mục tiêu tài chính'!$X$221:$X$250,'Cân đối lộ trình nghề nghiệp'!E25,'Mục tiêu tài chính'!$AA$221:$AA$250) -> 0.057341131 | M25: =SUMIF('Mục tiêu tài chính'!$X$221:$X$250,'Cân đối lộ trình nghề nghiệp'!E25,'Mục tiêu tài chính'!$AB$221:$AB$250) -> 0.16940238 | O25: =SUMIF('Mục tiêu tài chính'!$X$221:$X$250,'Cân đối lộ trình nghề nghiệp'!E25,'Mục tiêu tài chính'!$V$221:$V$250) -> 0.11061136 | Q25: Kỹ năng leader, kỹ năng xây dựng mô hình kinh doanh
E26: =E25+5 -> 31 | F26: =SUMIF('Mục tiêu tài chính'!$F$107:$F$145,'Cân đối lộ trình nghề nghiệp'!E26,'Mục tiêu tài chính'!$AB$107:$AC$145) -> 15.408232 | G26: =SUMIF('Mục tiêu tài chính'!$X$221:$X$250,'Cân đối lộ trình nghề nghiệp'!E26,'Mục tiêu tài chính'!$Y$221:$Y$250) -> 0.81332502 | I26: =SUMIF('Mục tiêu tài chính'!$X$221:$X$250,'Cân đối lộ trình nghề nghiệp'!E26,'Mục tiêu tài chính'!$Z$221:$Z$250) -> 0 | K26: =SUMIF('Mục tiêu tài chính'!$X$221:$X$250,'Cân đối lộ trình nghề nghiệp'!E26,'Mục tiêu tài chính'!$AA$221:$AA$250) -> 0.10741774 | M26: =SUMIF('Mục tiêu tài chính'!$X$221:$X$250,'Cân đối lộ trình nghề nghiệp'!E26,'Mục tiêu tài chính'!$AB$221:$AB$250) -> 0.07925724 | O26: =SUMIF('Mục tiêu tài chính'!$X$221:$X$250,'Cân đối lộ trình nghề nghiệp'!E26,'Mục tiêu tài chính'!$V$221:$V$250) -> 0.12276682 | Q26: Kỹ năng lãnh đạo
E27: =E26+5 -> 36 | F27: =SUMIF('Mục tiêu tài chính'!$F$107:$F$145,'Cân đối lộ trình nghề nghiệp'!E27,'Mục tiêu tài chính'!$AB$107:$AC$145) -> 10.469126 | G27: =SUMIF('Mục tiêu tài chính'!$X$221:$X$250,'Cân đối lộ trình nghề nghiệp'!E27,'Mục tiêu tài chính'!$Y$221:$Y$250) -> 0.45451928 | I27: =SUMIF('Mục tiêu tài chính'!$X$221:$X$250,'Cân đối lộ trình nghề nghiệp'!E27,'Mục tiêu tài chính'!$Z$221:$Z$250) -> 0 | K27: =SUMIF('Mục tiêu tài chính'!$X$221:$X$250,'Cân đối lộ trình nghề nghiệp'!E27,'Mục tiêu tài chính'!$AA$221:$AA$250) -> 0.32974635 | M27: =SUMIF('Mục tiêu tài chính'!$X$221:$X$250,'Cân đối lộ trình nghề nghiệp'!E27,'Mục tiêu tài chính'!$AB$221:$AB$250) -> 0.21573437 | O27: =SUMIF('Mục tiêu tài chính'!$X$221:$X$250,'Cân đối lộ trình nghề nghiệp'!E27,'Mục tiêu tài chính'!$V$221:$V$250) -> 0.099512302 | Q27: Kỹ năng quản lý doanh nghiệp
E28: =E27+5 -> 41 | F28: =SUMIF('Mục tiêu tài chính'!$F$107:$F$145,'Cân đối lộ trình nghề nghiệp'!E28,'Mục tiêu tài chính'!$AB$107:$AC$145) -> 3.8250819 | G28: =SUMIF('Mục tiêu tài chính'!$X$221:$X$250,'Cân đối lộ trình nghề nghiệp'!E28,'Mục tiêu tài chính'!$Y$221:$Y$250) -> 0.32331412 | I28: =SUMIF('Mục tiêu tài chính'!$X$221:$X$250,'Cân đối lộ trình nghề nghiệp'!E28,'Mục tiêu tài chính'!$Z$221:$Z$250) -> 0 | K28: =SUMIF('Mục tiêu tài chính'!$X$221:$X$250,'Cân đối lộ trình nghề nghiệp'!E28,'Mục tiêu tài chính'!$AA$221:$AA$250) -> 0.45056977 | M28: =SUMIF('Mục tiêu tài chính'!$X$221:$X$250,'Cân đối lộ trình nghề nghiệp'!E28,'Mục tiêu tài chính'!$AB$221:$AB$250) -> 0.22611611 | O28: =SUMIF('Mục tiêu tài chính'!$X$221:$X$250,'Cân đối lộ trình nghề nghiệp'!E28,'Mục tiêu tài chính'!$V$221:$V$250) -> 0.091503515 | Q28: Kỹ năng tạo lập cộng đồng
E29: =E28+5 -> 46 | F29: =SUMIF('Mục tiêu tài chính'!$F$107:$F$145,'Cân đối lộ trình nghề nghiệp'!E29,'Mục tiêu tài chính'!$AB$107:$AC$145) -> 3.8250819 | G29: =SUMIF('Mục tiêu tài chính'!$X$221:$X$250,'Cân đối lộ trình nghề nghiệp'!E29,'Mục tiêu tài chính'!$Y$221:$Y$250) -> 0.20819621 | I29: =SUMIF('Mục tiêu tài chính'!$X$221:$X$250,'Cân đối lộ trình nghề nghiệp'!E29,'Mục tiêu tài chính'!$Z$221:$Z$250) -> 0 | K29: =SUMIF('Mục tiêu tài chính'!$X$221:$X$250,'Cân đối lộ trình nghề nghiệp'!E29,'Mục tiêu tài chính'!$AA$221:$AA$250) -> 0.58074219 | M29: =SUMIF('Mục tiêu tài chính'!$X$221:$X$250,'Cân đối lộ trình nghề nghiệp'!E29,'Mục tiêu tài chính'!$AB$221:$AB$250) -> 0.21106159 | O29: =SUMIF('Mục tiêu tài chính'!$X$221:$X$250,'Cân đối lộ trình nghề nghiệp'!E29,'Mục tiêu tài chính'!$V$221:$V$250) -> 0.085144229
E31: Phần 2: Xây dựng lộ trình nghề nghiệp chi tiết
E34: Số tuổi | F34: Thu nhập thực tế | G34: Số tiền cần có để đạt mục tiêu tài chính | H34: Thu nhập theo lộ trình nghề nghiệp
E37: 22 | F37: 10 | H37: 12
E38: 23 | F38: 15 | H38: 12
E39: 24 | F39: 20 | G39: =F39 -> 20 | H39: 12
E40: 25 | G40: ='Mục tiêu tài chính'!AB107 -> 6.4022011 | H40: 15
E41: 26 | G41: ='Mục tiêu tài chính'!AB108 -> 10.41867 | H41: 20
E42: 27 | G42: ='Mục tiêu tài chính'!AB109 -> 17.670088 | H42: 20
E43: 28 | G43: ='Mục tiêu tài chính'!AB110 -> 17.670088 | H43: 20
E44: 29 | G44: ='Mục tiêu tài chính'!AB111 -> 11.267887 | H44: 20
E45: 30 | G45: ='Mục tiêu tài chính'!AB112 -> 28.502823 | H45: 20
E46: 31 | G46: ='Mục tiêu tài chính'!AB113 -> 28.502823 | H46: 20
E47: 32 | G47: ='Mục tiêu tài chính'!AB114 -> 30.015592 | H47: 25
E48: 33 | G48: ='Mục tiêu tài chính'!AB115 -> 32.643168 | H48: 25
E49: 34 | G49: ='Mục tiêu tài chính'!AB116 -> 32.643168 | H49: 25
E50: 35 | G50: ='Mục tiêu tài chính'!AB117 -> 15.408232 | H50: 25
E51: 36 | G51: ='Mục tiêu tài chính'!AB118 -> 15.408232 | H51: 30
... E74: 59 | G74: ='Mục tiêu tài chính'!AB141 -> 0 | H74: 60
E75: 60 | G75: ='Mục tiêu tài chính'!AB142 -> 0
E76: 61 | G76: ='Mục tiêu tài chính'!AB143 -> 0
E77: 62 | G77: ='Mục tiêu tài chính'!AB144 -> 0
E78: 63 | G78: ='Mục tiêu tài chính'!AB145 -> 0
E79: 64 | G79: ='Mục tiêu tài chính'!AB146 -> 0
E80: 65 | G80: ='Mục tiêu tài chính'!AB147 -> 0
E81: 66 | G81: ='Mục tiêu tài chính'!AB148 -> 0
E82: 67 | G82: ='Mục tiêu tài chính'!AB149 -> 0
E83: 68 | G83: ='Mục tiêu tài chính'!AB150 -> 0
E84: 69 | G84: ='Mục tiêu tài chính'!AB151 -> 0
...

Sheet Kế hoạch thu nhập và chi tiêu
E1: KẾ HOẠCH THU NHẬP VÀ CHI TIÊU CHO TỪNG THÁNG
R3: Đơn vị: triệu đồng
F4: Phần 1 | G4: Phần 2
E6: Phần 1: Kế hoạch thu nhập trong tháng
E9: Danh mục thu nhập
E10: # | F10: Khoản mục | L10: Kế hoạch thu nhập | N10: Diễn giải | V10: Phân tích
E11: ='Từ khóa'!L12 -> 1 | F11: ='Từ khóa'!M12 -> Lương từ công ty | L11: 20
E12: ='Từ khóa'!L13 -> 2 | F12: ='Từ khóa'!M13 -> Thu nhập khác | L12: 10
E13: ='Từ khóa'!L14 -> 3 | F13: ='Từ khóa'!M14 -> 0
E14: ='Từ khóa'!L15 -> 4 | F14: ='Từ khóa'!M15 -> 0
E15: ='Từ khóa'!L16 -> 5 | F15: ='Từ khóa'!M16 -> 0
E16: ='Từ khóa'!L17 -> 6 | F16: ='Từ khóa'!M17 -> 0
E17: ='Từ khóa'!L18 -> 7 | F17: ='Từ khóa'!M18 -> 0
E18: ='Từ khóa'!L19 -> 8 | F18: ='Từ khóa'!M19 -> 0
E19: Tổng thu nhập | L19: =SUM(L11:M18) -> 30
E21: Phần 2: Kế hoạch chi tiêu
E24: Danh mục chi tiêu
E25: # | F25: Khoản mục | L25: Kế hoạch chi tiêu | N25: Diễn giải | V25: Phân tích
E26: ='Từ khóa'!E12 -> 1 | F26: ='Từ khóa'!F12 -> Mua thực phẩm | L26: 5
E27: ='Từ khóa'!E13 -> 2 | F27: ='Từ khóa'!F13 -> Mua đồ dùng trong nhà | L27: 0.5 | M27: 1
E28: ='Từ khóa'!E14 -> 3 | F28: ='Từ khóa'!F14 -> Đi ăn ở ngoài | L28: 2 | M28: 0.5
E29: ='Từ khóa'!E15 -> 4 | F29: ='Từ khóa'!F15 -> Chi tiền phát triển bản thân | L29: 1.5 | M29: 11
E30: ='Từ khóa'!E16 -> 5 | F30: ='Từ khóa'!F16 -> Chi tiền bảo hiểm | L30: 0 | M30: 4.5
E31: ='Từ khóa'!E17 -> 6 | F31: ='Từ khóa'!F17 -> Chi tiền điện, nước, internet, điện thoại, xăng xe | L31: 2 | M31: 2
E32: ='Từ khóa'!E18 -> 7 | F32: ='Từ khóa'!F18 -> Chi tiền giải trí, quà tặng | L32: 0 | M32: 0.5
E33: ='Từ khóa'!E19 -> 8 | F33: ='Từ khóa'!F19 -> Chi tiền cho con | L33: 0 | M33: 7
E34: ='Từ khóa'!E20 -> 9 | F34: ='Từ khóa'!F20 -> Chi tiền trả nợ | L34: 6.5 | M34: 13.7
E35: ='Từ khóa'!E21 -> 10 | F35: ='Từ khóa'!F21 -> Chi tiền cho tặng gia đình | L35: 1 | M35: 1
E36: ='Từ khóa'!E22 -> 11 | F36: ='Từ khóa'!F22 -> Chi tiêu 1 | L36: 0 | M36: 0
E37: ='Từ khóa'!E23 -> 12 | F37: ='Từ khóa'!F23 -> Chi tiêu 2 | L37: 0 | M37: 0
E38: ='Từ khóa'!E24 -> 13 | F38: ='Từ khóa'!F24 -> Chi tiêu 3 | L38: 0 | M38: 0
... E40: ='Từ khóa'!E26 -> 15 | F40: ='Từ khóa'!F26 -> Chi tiêu 5 | L40: 0 | M40: 0
E41: Tổng chi tiêu | L41: =SUM(L26:L40) -> 18.5

Sheet T1
E1: THEO DÕI THU - CHI THÁNG 1
L3: Đơn vị: triệu đồng
F4: Phần 1 | G4: Phần 2
E6: Phần 1: Theo dõi thu chi
E9: Tổng thu nhập | I9: =N37 -> 24
E14: Tổng chi phí | I14: =N83 -> 17.5
E19: Tiết kiệm | I19: =I9-I14 -> 6.5
E25: Thu nhập chi tiết | P25: Tổng kết thu nhập
E26: Thời gian | G26: Các khoản thu nhập | K26: Mô tả chi tiết | N26: Tổng | P26: Danh mục | T26: Kế hoạch | V26: Thực tế | X26: Chênh lệch | Z26: Lý do | AF26: Biện pháp
E27: 44576 | G27: Lương từ công ty | N27: 20 | P27: ='Từ khóa'!M12 -> Lương từ công ty | T27: ='Kế hoạch thu nhập và chi tiêu'!L11 -> 20 | W27: =SUMIF($G$27:$J$36,P27,$N$27:$N$36) -> 20 | X27: =W27-T27 -> 0 | Z27: Thưởng KPI
E28: 44591 | G28: Thu nhập khác | N28: 4 | P28: ='Từ khóa'!M13 -> Thu nhập khác | T28: ='Kế hoạch thu nhập và chi tiêu'!L12 -> 10 | W28: =SUMIF($G$27:$J$36,P28,$N$27:$N$36) -> 4 | X28: =W28-T28 -> -6
P29: ='Từ khóa'!M14 -> 0 | T29: ='Kế hoạch thu nhập và chi tiêu'!L13 -> 0 | W29: =SUMIF($G$27:$J$36,P29,$N$27:$N$36) -> 0 | X29: =W29-T29 -> 0
P30: ='Từ khóa'!M15 -> 0 | T30: ='Kế hoạch thu nhập và chi tiêu'!L14 -> 0 | W30: =SUMIF($G$27:$J$36,P30,$N$27:$N$36) -> 0 | X30: =W30-T30 -> 0
P31: ='Từ khóa'!M16 -> 0 | T31: ='Kế hoạch thu nhập và chi tiêu'!L15 -> 0 | W31: =SUMIF($G$27:$J$36,P31,$N$27:$N$36) -> 0 | X31: =W31-T31 -> 0
P32: ='Từ khóa'!M17 -> 0 | T32: ='Kế hoạch thu nhập và chi tiêu'!L16 -> 0 | W32: =SUMIF($G$27:$J$36,P32,$N$27:$N$36) -> 0 | X32: =W32-T32 -> 0
P33: ='Từ khóa'!M18 -> 0 | T33: ='Kế hoạch thu nhập và chi tiêu'!L17 -> 0 | W33: =SUMIF($G$27:$J$36,P33,$N$27:$N$36) -> 0 | X33: =W33-T33 -> 0
P34: ='Từ khóa'!M19 -> 0 | T34: ='Kế hoạch thu nhập và chi tiêu'!L18 -> 0 | W34: =SUMIF($G$27:$J$36,P34,$N$27:$N$36) -> 0 | X34: =W34-T34 -> 0
E37: Tổng thu nhập | N37: =SUBTOTAL(109,'T1'!$N$27:$N$36) -> 24 | P37: Tổng thu nhập | T37: =SUM(T27:U36) -> 30 | V37: =SUM(W27:W36) -> 24 | X37: =SUM(X27:Y36) -> -6
E40: Chi tiêu chi tiết | P40: Tổng kết chi tiêu
E41: Thời gian | G41: Các khoản chi tiêu | K41: Mô tả chi tiết | N41: Tổng | P41: Danh mục | T41: Kế hoạch | V41: Thực tế | X41: Chênh lệch | Z41: Lý do | AF41: Biện pháp
E42: 44562 | G42: Mua thực phẩm | K42: Mua rau củ quả, gạo | N42: 5.5 | P42: ='Từ khóa'!F12 -> Mua thực phẩm | T42: ='Kế hoạch thu nhập và chi tiêu'!L26 -> 5 | W42: =SUMIF($G$42:$J$82,P42,$N$42:$N$82) -> 5.5 | X42: =T42-W42 -> -0.5 | Z42: Mua sắm tết | AF42: Giảm chi tiêu tháng sau
E43: 44565 | G43: Mua đồ dùng trong nhà | K43: Mua máy ép | N43: 0.3 | P43: ='Từ khóa'!F13 -> Mua đồ dùng trong nhà | T43: ='Kế hoạch thu nhập và chi tiêu'!L27 -> 0.5 | W43: =SUMIF($G$42:$J$82,P43,$N$42:$N$82) -> 0.3 | X43: =T43-W43 -> 0.2
E44: 44568 | G44: Đi ăn ở ngoài | K44: Đi gặp bạn cũ | N44: 0.2 | P44: ='Từ khóa'!F14 -> Đi ăn ở ngoài | T44: ='Kế hoạch thu nhập và chi tiêu'!L28 -> 2 | W44: =SUMIF($G$42:$J$82,P44,$N$42:$N$82) -> 0.8 | X44: =T44-W44 -> 1.2
E45: 44571 | G45: Đi ăn ở ngoài | N45: 0.6 | P45: ='Từ khóa'!F15 -> Chi tiền phát triển bản thân | T45: ='Kế hoạch thu nhập và chi tiêu'!L29 -> 1.5 | W45: =SUMIF($G$42:$J$82,P45,$N$42:$N$82) -> 1.1 | X45: =T45-W45 -> 0.4
E46: 44589 | G46: Chi tiền điện, nước, internet, điện thoại, xăng xe | K46: Điện | N46: 0.5 | P46: ='Từ khóa'!F16 -> Chi tiền bảo hiểm | T46: ='Kế hoạch thu nhập và chi tiêu'!L30 -> 0 | W46: =SUMIF($G$42:$J$82,P46,$N$42:$N$82) -> 0 | X46: =T46-W46 -> 0
E47: 44590 | G47: Chi tiền điện, nước, internet, điện thoại, xăng xe | K47: Nước | N47: 0.3 | P47: ='Từ khóa'!F17 -> Chi tiền điện, nước, internet, điện thoại, xăng xe | T47: ='Kế hoạch thu nhập và chi tiêu'!L31 -> 2 | W47: =SUMIF($G$42:$J$82,P47,$N$42:$N$82) -> 1.3 | X47: =T47-W47 -> 0.7
E48: 44591 | G48: Chi tiền điện, nước, internet, điện thoại, xăng xe | K48: Internet | N48: 0.3 | P48: ='Từ khóa'!F18 -> Chi tiền giải trí, quà tặng | T48: ='Kế hoạch thu nhập và chi tiêu'!L32 -> 0 | W48: =SUMIF($G$42:$J$82,P48,$N$42:$N$82) -> 0 | X48: =T48-W48 -> 0
E49: 44576 | G49: Chi tiền điện, nước, internet, điện thoại, xăng xe | K49: Xăng | N49: 0.2 | P49: ='Từ khóa'!F19 -> Chi tiền cho con | T49: ='Kế hoạch thu nhập và chi tiêu'!L33 -> 0 | W49: =SUMIF($G$42:$J$82,P49,$N$42:$N$82) -> 0 | X49: =T49-W49 -> 0
E50: 44571 | G50: Chi tiền trả nợ | N50: 6.5 | P50: ='Từ khóa'!F20 -> Chi tiền trả nợ | T50: ='Kế hoạch thu nhập và chi tiêu'!L34 -> 6.5 | W50: =SUMIF($G$42:$J$82,P50,$N$42:$N$82) -> 6.5 | X50: =T50-W50 -> 0
E51: 44566 | G51: Chi tiền cho tặng gia đình | N51: 2 | P51: ='Từ khóa'!F21 -> Chi tiền cho tặng gia đình | T51: ='Kế hoạch thu nhập và chi tiêu'!L35 -> 1 | W51: =SUMIF($G$42:$J$82,P51,$N$42:$N$82) -> 2 | X51: =T51-W51 -> -1
E52: 44562 | G52: Chi tiền phát triển bản thân | K52: Mua sách | N52: 0.1 | P52: ='Từ khóa'!F22 -> Chi tiêu 1 | T52: ='Kế hoạch thu nhập và chi tiêu'!L36 -> 0 | W52: =SUMIF($G$42:$J$82,P52,$N$42:$N$82) -> 0 | X52: =T52-W52 -> 0
E53: 44573 | G53: Chi tiền phát triển bản thân | K53: Học lập trình | N53: 1 | P53: ='Từ khóa'!F23 -> Chi tiêu 2 | T53: ='Kế hoạch thu nhập và chi tiêu'!L37 -> 0 | W53: =SUMIF($G$42:$J$82,P53,$N$42:$N$82) -> 0 | X53: =T53-W53 -> 0
P54: ='Từ khóa'!F24 -> Chi tiêu 3 | T54: ='Kế hoạch thu nhập và chi tiêu'!L38 -> 0 | W54: =SUMIF($G$42:$J$82,P54,$N$42:$N$82) -> 0 | X54: =T54-W54 -> 0
P55: ='Từ khóa'!F25 -> Chi tiêu 4 | T55: ='Kế hoạch thu nhập và chi tiêu'!L39 -> 0 | W55: =SUMIF($G$42:$J$82,P55,$N$42:$N$82) -> 0 | X55: =T55-W55 -> 0
P56: ='Từ khóa'!F26 -> Chi tiêu 5 | T56: ='Kế hoạch thu nhập và chi tiêu'!L40 -> 0 | X56: =T56-W56 -> 0
P57: Tổng chi tiêu | T57: =SUM(T42:U56) -> 18.5 | V57: =SUM(W42:W56) -> 17.5 | X57: =SUM(X42:Y56) -> 1
E83: Tổng chi tiêu | N83: =SUM(N42:N82) -> 17.5
E86: Phần 2: Các khoản đầu tư phát triển bản thân chi tiết
E89: Các khoản đầu tư phát triển bản thân chi tiết | AA89: Thống kê các khoản chi đầu tư phát triển bản thân
E90: Thời gian | G90: Các khoản đầu tư | I90: Mô tả chi tiết | K90: Tổng | L90: Kết quả tạo ra dự kiến | S90: Kết quả tạo ra thực tế | AA90: Danh mục | AE90: Giá trị đầu tư
...

Sheet T2
E1: THEO DÕI THU - CHI THÁNG 2
L3: Đơn vị: triệu đồng
F4: Phần 1 | G4: Phần 2
E6: Phần 1: Theo dõi thu chi
E9: Tổng thu nhập | I9: =N37 -> 29.5
E14: Tổng chi phí | I14: =N83 -> 19.2
E19: Tiết kiệm | I19: =I9-I14 -> 10.3
E25: Thu nhập chi tiết | P25: Tổng kết thu nhập
E26: Thời gian | G26: Các khoản thu nhập | K26: Mô tả chi tiết | N26: Tổng | P26: Danh mục | T26: Kế hoạch | V26: Thực tế | X26: Chênh lệch | Z26: Lý do | AF26: Biện pháp
E27: 44607 | G27: Lương từ công ty | N27: 25 | P27: ='Từ khóa'!M12 -> Lương từ công ty | T27: ='Kế hoạch thu nhập và chi tiêu'!L11 -> 20 | W27: =SUMIF($G$27:$J$36,P27,$N$27:$N$36) -> 25 | X27: =W27-T27 -> 5 | Z27: Thưởng tết
E28: 44612 | F28: 44612 | G28: Thu nhập khác | N28: 1 | P28: ='Từ khóa'!M13 -> Thu nhập khác | T28: ='Kế hoạch thu nhập và chi tiêu'!L12 -> 10 | W28: =SUMIF($G$27:$J$36,P28,$N$27:$N$36) -> 4.5 | X28: =W28-T28 -> -5.5
E29: 44620 | F29: 44620 | G29: Thu nhập khác | N29: 1.5 | P29: ='Từ khóa'!M14 -> 0 | T29: ='Kế hoạch thu nhập và chi tiêu'!L13 -> 0 | W29: =SUMIF($G$27:$J$36,P29,$N$27:$N$36) -> 0 | X29: =W29-T29 -> 0
E30: 44620 | F30: 44620 | G30: Thu nhập khác | N30: 2 | P30: ='Từ khóa'!M15 -> 0 | T30: ='Kế hoạch thu nhập và chi tiêu'!L14 -> 0 | W30: =SUMIF($G$27:$J$36,P30,$N$27:$N$36) -> 0 | X30: =W30-T30 -> 0
P31: ='Từ khóa'!M16 -> 0 | T31: ='Kế hoạch thu nhập và chi tiêu'!L15 -> 0 | W31: =SUMIF($G$27:$J$36,P31,$N$27:$N$36) -> 0 | X31: =W31-T31 -> 0
P32: ='Từ khóa'!M17 -> 0 | T32: ='Kế hoạch thu nhập và chi tiêu'!L16 -> 0 | W32: =SUMIF($G$27:$J$36,P32,$N$27:$N$36) -> 0 | X32: =W32-T32 -> 0
P33: ='Từ khóa'!M18 -> 0 | T33: ='Kế hoạch thu nhập và chi tiêu'!L17 -> 0 | W33: =SUMIF($G$27:$J$36,P33,$N$27:$N$36) -> 0 | X33: =W33-T33 -> 0
P34: ='Từ khóa'!M19 -> 0 | T34: ='Kế hoạch thu nhập và chi tiêu'!L18 -> 0 | W34: =SUMIF($G$27:$J$36,P34,$N$27:$N$36) -> 0 | X34: =W34-T34 -> 0
E37: Tổng thu nhập | N37: =SUBTOTAL(109,'T2'!$N$27:$N$36) -> 29.5 | P37: Tổng thu nhập | T37: =SUM(T27:U36) -> 30 | V37: =SUM(W27:W36) -> 29.5 | X37: =SUM(X27:Y36) -> -0.5
E40: Chi tiêu chi tiết | P40: Tổng kết chi tiêu
E41: Thời gian | G41: Các khoản chi tiêu | K41: Mô tả chi tiết | N41: Tổng | P41: Danh mục | T41: Kế hoạch | V41: Thực tế | X41: Chênh lệch | Z41: Lý do | AF41: Biện pháp
E42: 44593 | F42: 44593 | G42: Mua thực phẩm | N42: 5 | P42: ='Từ khóa'!F12 -> Mua thực phẩm | T42: ='Kế hoạch thu nhập và chi tiêu'!L26 -> 5 | W42: =SUMIF($G$42:$J$82,P42,$N$42:$N$82) -> 5 | X42: =T42-W42 -> 0
E43: 44593 | F43: 44593 | G43: Mua đồ dùng trong nhà | H43: Mua đồ dùng trong nhà | I43: Mua đồ dùng trong nhà | J43: Mua đồ dùng trong nhà | N43: 0.4 | P43: ='Từ khóa'!F13 -> Mua đồ dùng trong nhà | T43: ='Kế hoạch thu nhập và chi tiêu'!L27 -> 0.5 | W43: =SUMIF($G$42:$J$82,P43,$N$42:$N$82) -> 0.7 | X43: =T43-W43 -> -0.2 | Z43: Mua sắm các đồ dùng mới thay cho đồ dùng cũ
E44: 44594 | F44: 44594 | G44: Chi tiền điện, nước, internet, điện thoại, xăng xe | H44: Chi tiền điện, nước, internet, điện thoại, xăng xe | I44: Chi tiền điện, nước, internet, điện thoại, xăng xe | J44: Chi tiền điện, nước, internet, điện thoại, xăng xe | K44: Tiền điện | L44: Tiền điện | M44: Tiền điện | N44: 0.4 | P44: ='Từ khóa'!F14 -> Đi ăn ở ngoài | T44: ='Kế hoạch thu nhập và chi tiêu'!L28 -> 2 | W44: =SUMIF($G$42:$J$82,P44,$N$42:$N$82) -> 1.8 | X44: =T44-W44 -> 0.2 | Z44: Phát sinh nhiều tiệc cưới và đi ăn với khách hàng | AF44: Giảm chi tiêu tháng sau
E45: 44595 | F45: 44595 | G45: Chi tiền điện, nước, internet, điện thoại, xăng xe | H45: Chi tiền điện, nước, internet, điện thoại, xăng xe | I45: Chi tiền điện, nước, internet, điện thoại, xăng xe | J45: Chi tiền điện, nước, internet, điện thoại, xăng xe | K45: Tiền nước | L45: Tiền nước | M45: Tiền nước | N45: 0.3 | P45: ='Từ khóa'!F15 -> Chi tiền phát triển bản thân | T45: ='Kế hoạch thu nhập và chi tiêu'!L29 -> 1.5 | W45: =SUMIF($G$42:$J$82,P45,$N$42:$N$82) -> 2.3 | X45: =T45-W45 -> -0.8 | Z45: Cần bổ sung các kiến thức cần thiết
E46: 44596 | F46: 44596 | G46: Chi tiền điện, nước, internet, điện thoại, xăng xe | H46: Chi tiền điện, nước, internet, điện thoại, xăng xe | I46: Chi tiền điện, nước, internet, điện thoại, xăng xe | J46: Chi tiền điện, nước, internet, điện thoại, xăng xe | K46: Tiền wifi | L46: Tiền wifi | M46: Tiền wifi | N46: 0.3 | P46: ='Từ khóa'!F16 -> Chi tiền bảo hiểm | T46: ='Kế hoạch thu nhập và chi tiêu'!L30 -> 0 | W46: =SUMIF($G$42:$J$82,P46,$N$42:$N$82) -> 0 | X46: =T46-W46 -> 0
E47: 44597 | F47: 44597 | G47: Chi tiền điện, nước, internet, điện thoại, xăng xe | H47: Chi tiền điện, nước, internet, điện thoại, xăng xe | I47: Chi tiền điện, nước, internet, điện thoại, xăng xe | J47: Chi tiền điện, nước, internet, điện thoại, xăng xe | K47: Tiền xăng | L47: Tiền xăng | M47: Tiền xăng | N47: 0.3 | P47: ='Từ khóa'!F17 -> Chi tiền điện, nước, internet, điện thoại, xăng xe | T47: ='Kế hoạch thu nhập và chi tiêu'!L31 -> 2 | W47: =SUMIF($G$42:$J$82,P47,$N$42:$N$82) -> 1.6 | X47: =T47-W47 -> 0.4 | Z47: Giá xăng tăng mạnh | AF47: Chỉ đi lại khi cần thiết
E48: 44599 | F48: 44599 | G48: Chi tiền điện, nước, internet, điện thoại, xăng xe | H48: Chi tiền điện, nước, internet, điện thoại, xăng xe | I48: Chi tiền điện, nước, internet, điện thoại, xăng xe | J48: Chi tiền điện, nước, internet, điện thoại, xăng xe | K48: Tiền điện thoại | L48: Tiền điện thoại | M48: Tiền điện thoại | N48: 0.1 | P48: ='Từ khóa'!F18 -> Chi tiền giải trí, quà tặng | T48: ='Kế hoạch thu nhập và chi tiêu'!L32 -> 0 | W48: =SUMIF($G$42:$J$82,P48,$N$42:$N$82) -> 0 | X48: =T48-W48 -> 0
E49: 44601 | F49: 44601 | G49: Đi ăn ở ngoài | H49: Đi ăn ở ngoài | I49: Đi ăn ở ngoài | J49: Đi ăn ở ngoài | N49: 0.5 | P49: ='Từ khóa'!F19 -> Chi tiền cho con | T49: ='Kế hoạch thu nhập và chi tiêu'!L33 -> 0 | W49: =SUMIF($G$42:$J$82,P49,$N$42:$N$82) -> 0 | X49: =T49-W49 -> 0
E50: 44603 | F50: 44603 | G50: Chi tiền phát triển bản thân | H50: Chi tiền phát triển bản thân | I50: Chi tiền phát triển bản thân | J50: Chi tiền phát triển bản thân | K50: Mua sách | L50: Mua sách | M50: Mua sách | N50: 0.5 | P50: ='Từ khóa'!F20 -> Chi tiền trả nợ | T50: ='Kế hoạch thu nhập và chi tiêu'!L34 -> 6.5 | W50: =SUMIF($G$42:$J$82,P50,$N$42:$N$82) -> 6.5 | X50: =T50-W50 -> 0
E51: 44604 | F51: 44604 | G51: Chi tiền phát triển bản thân | H51: Chi tiền phát triển bản thân | I51: Chi tiền phát triển bản thân | J51: Chi tiền phát triển bản thân | K51: Khóa học | L51: Khóa học | M51: Khóa học | N51: 1 | P51: ='Từ khóa'!F21 -> Chi tiền cho tặng gia đình | T51: ='Kế hoạch thu nhập và chi tiêu'!L35 -> 1 | W51: =SUMIF($G$42:$J$82,P51,$N$42:$N$82) -> 1.3 | X51: =T51-W51 -> -0.3
E52: 44612 | F52: 44612 | G52: Chi tiền phát triển bản thân | K52: Chi phát triển bản thân khác | N52: 0.8 | P52: ='Từ khóa'!F22 -> Chi tiêu 1 | T52: ='Kế hoạch thu nhập và chi tiêu'!L36 -> 0 | W52: =SUMIF($G$42:$J$82,P52,$N$42:$N$82) -> 0 | X52: =T52-W52 -> 0
E53: 44614 | F53: 22/02/2022 | G53: Đi ăn ở ngoài | N53: 0.3 | P53: ='Từ khóa'!F23 -> Chi tiêu 2 | T53: ='Kế hoạch thu nhập và chi tiêu'!L37 -> 0 | W53: =SUMIF($G$42:$J$82,P53,$N$42:$N$82) -> 0 | X53: =T53-W53 -> 0
E54: 44615 | F54: 44615 | G54: Đi ăn ở ngoài | N54: 0.4 | P54: ='Từ khóa'!F24 -> Chi tiêu 3 | T54: ='Kế hoạch thu nhập và chi tiêu'!L38 -> 0 | W54: =SUMIF($G$42:$J$82,P54,$N$42:$N$82) -> 0 | X54: =T54-W54 -> 0
E55: 44616 | F55: 44616 | G55: Mua đồ dùng trong nhà | N55: 0.3 | P55: ='Từ khóa'!F25 -> Chi tiêu 4 | T55: ='Kế hoạch thu nhập và chi tiêu'!L39 -> 0 | W55: =SUMIF($G$42:$J$82,P55,$N$42:$N$82) -> 0 | X55: =T55-W55 -> 0
E56: 44617 | F56: 44617 | G56: Chi tiền điện, nước, internet, điện thoại, xăng xe | K56: Tiền xăng | N56: 0.2 | P56: ='Từ khóa'!F26 -> Chi tiêu 5 | T56: ='Kế hoạch thu nhập và chi tiêu'!L40 -> 0 | X56: =T56-W56 -> 0
E57: 44618 | F57: 44618 | G57: Chi tiền trả nợ | N57: 6.5 | P57: Tổng chi tiêu | T57: =SUM(T42:U56) -> 18.5 | V57: =SUM(W42:W56) -> 19.2 | X57: =SUM(X42:Y56) -> -0.7
E58: 44619 | F58: 44619 | G58: Chi tiền cho tặng gia đình | N58: 1.3
E59: 44620 | F59: 22/02/2022 | G59: Đi ăn ở ngoài | N59: 0.6
E83: Tổng chi tiêu | N83: =SUM(N42:N82) -> 19.2
E86: Phần 2: Các khoản đầu tư phát triển bản thân chi tiết
...

Sheet T3
E1: THEO DÕI THU - CHI THÁNG 3
L3: Đơn vị: triệu đồng
F4: Phần 1 | G4: Phần 2
E6: Phần 1: Theo dõi thu chi
E9: Tổng thu nhập | I9: =N37 -> 23.7
E14: Tổng chi phí | I14: =N83 -> 19.25
E19: Tiết kiệm | I19: =I9-I14 -> 4.45
E25: Thu nhập chi tiết | P25: Tổng kết thu nhập
E26: Thời gian | G26: Các khoản thu nhập | K26: Mô tả chi tiết | N26: Tổng | P26: Danh mục | T26: Kế hoạch | V26: Thực tế | X26: Chênh lệch | Z26: Lý do | AF26: Biện pháp
E27: 44635 | G27: Lương từ công ty | N27: 18 | P27: ='Từ khóa'!M12 -> Lương từ công ty | T27: ='Kế hoạch thu nhập và chi tiêu'!L11 -> 20 | W27: =SUMIF($G$27:$J$36,P27,$N$27:$N$36) -> 18 | X27: =W27-T27 -> -2
E28: 44640 | F28: 44612 | G28: Thu nhập khác | N28: 2 | P28: ='Từ khóa'!M13 -> Thu nhập khác | T28: ='Kế hoạch thu nhập và chi tiêu'!L12 -> 10 | W28: =SUMIF($G$27:$J$36,P28,$N$27:$N$36) -> 5.7 | X28: =W28-T28 -> -4.3
E29: 44648 | F29: 44620 | G29: Thu nhập khác | N29: 2.5 | P29: ='Từ khóa'!M14 -> 0 | T29: ='Kế hoạch thu nhập và chi tiêu'!L13 -> 0 | W29: =SUMIF($G$27:$J$36,P29,$N$27:$N$36) -> 0 | X29: =W29-T29 -> 0
E30: 44648 | F30: 44620 | G30: Thu nhập khác | N30: 1.2 | P30: ='Từ khóa'!M15 -> 0 | T30: ='Kế hoạch thu nhập và chi tiêu'!L14 -> 0 | W30: =SUMIF($G$27:$J$36,P30,$N$27:$N$36) -> 0 | X30: =W30-T30 -> 0
P31: ='Từ khóa'!M16 -> 0 | T31: ='Kế hoạch thu nhập và chi tiêu'!L15 -> 0 | W31: =SUMIF($G$27:$J$36,P31,$N$27:$N$36) -> 0 | X31: =W31-T31 -> 0
P32: ='Từ khóa'!M17 -> 0 | T32: ='Kế hoạch thu nhập và chi tiêu'!L16 -> 0 | W32: =SUMIF($G$27:$J$36,P32,$N$27:$N$36) -> 0 | X32: =W32-T32 -> 0
P33: ='Từ khóa'!M18 -> 0 | T33: ='Kế hoạch thu nhập và chi tiêu'!L17 -> 0 | W33: =SUMIF($G$27:$J$36,P33,$N$27:$N$36) -> 0 | X33: =W33-T33 -> 0
P34: ='Từ khóa'!M19 -> 0 | T34: ='Kế hoạch thu nhập và chi tiêu'!L18 -> 0 | W34: =SUMIF($G$27:$J$36,P34,$N$27:$N$36) -> 0 | X34: =W34-T34 -> 0
E37: Tổng thu nhập | N37: =SUBTOTAL(109,'T3'!$N$27:$N$36) -> 23.7 | P37: Tổng thu nhập | T37: =SUM(T27:U36) -> 30 | V37: =SUM(W27:W36) -> 23.7 | X37: =SUM(X27:Y36) -> -6.3
E40: Chi tiêu chi tiết | P40: Tổng kết chi tiêu
E41: Thời gian | G41: Các khoản chi tiêu | K41: Mô tả chi tiết | N41: Tổng | P41: Danh mục | T41: Kế hoạch | V41: Thực tế | X41: Chênh lệch | Z41: Lý do | AF41: Biện pháp
E42: 44621 | F42: 44593 | G42: Mua thực phẩm | N42: 6 | P42: ='Từ khóa'!F12 -> Mua thực phẩm | T42: ='Kế hoạch thu nhập và chi tiêu'!L26 -> 5 | W42: =SUMIF($G$42:$J$82,P42,$N$42:$N$82) -> 6.8 | X42: =T42-W42 -> -1.8 | Z42: Nhận thực phẩm từ gia đình
E43: 44621 | F43: 44593 | G43: Mua đồ dùng trong nhà | H43: Mua đồ dùng trong nhà | I43: Mua đồ dùng trong nhà | J43: Mua đồ dùng trong nhà | N43: 0.4 | P43: ='Từ khóa'!F13 -> Mua đồ dùng trong nhà | T43: ='Kế hoạch thu nhập và chi tiêu'!L27 -> 0.5 | W43: =SUMIF($G$42:$J$82,P43,$N$42:$N$82) -> 1.1 | X43: =T43-W43 -> -0.6 | Z43: Mua đồ dùng cần thiết
E44: 44622 | F44: 44594 | G44: Chi tiền điện, nước, internet, điện thoại, xăng xe | H44: Chi tiền điện, nước, internet, điện thoại, xăng xe | I44: Chi tiền điện, nước, internet, điện thoại, xăng xe | J44: Chi tiền điện, nước, internet, điện thoại, xăng xe | K44: Tiền điện | L44: Tiền điện | M44: Tiền điện | N44: 0.6 | P44: ='Từ khóa'!F14 -> Đi ăn ở ngoài | T44: ='Kế hoạch thu nhập và chi tiêu'!L28 -> 2 | W44: =SUMIF($G$42:$J$82,P44,$N$42:$N$82) -> 0.5 | X44: =T44-W44 -> 1.5
E45: 44623 | F45: 44595 | G45: Chi tiền điện, nước, internet, điện thoại, xăng xe | H45: Chi tiền điện, nước, internet, điện thoại, xăng xe | I45: Chi tiền điện, nước, internet, điện thoại, xăng xe | J45: Chi tiền điện, nước, internet, điện thoại, xăng xe | K45: Tiền nước | L45: Tiền nước | M45: Tiền nước | N45: 0.2 | P45: ='Từ khóa'!F15 -> Chi tiền phát triển bản thân | T45: ='Kế hoạch thu nhập và chi tiêu'!L29 -> 1.5 | W45: =SUMIF($G$42:$J$82,P45,$N$42:$N$82) -> 1.5 | X45: =T45-W45 -> 0 | Z45: Cần bổ sung các kiến thức cần thiết
E46: 44624 | F46: 44596 | G46: Chi tiền điện, nước, internet, điện thoại, xăng xe | H46: Chi tiền điện, nước, internet, điện thoại, xăng xe | I46: Chi tiền điện, nước, internet, điện thoại, xăng xe | J46: Chi tiền điện, nước, internet, điện thoại, xăng xe | K46: Tiền wifi | L46: Tiền wifi | M46: Tiền wifi | N46: 0.3 | P46: ='Từ khóa'!F16 -> Chi tiền bảo hiểm | T46: ='Kế hoạch thu nhập và chi tiêu'!L30 -> 0 | W46: =SUMIF($G$42:$J$82,P46,$N$42:$N$82) -> 0.5 | X46: =T46-W46 -> -0.5 | Z46: Chi bảo hiểm y tế toàn dân thời hạn 1 năm
E47: 44625 | F47: 44597 | G47: Chi tiền điện, nước, internet, điện thoại, xăng xe | H47: Chi tiền điện, nước, internet, điện thoại, xăng xe | I47: Chi tiền điện, nước, internet, điện thoại, xăng xe | J47: Chi tiền điện, nước, internet, điện thoại, xăng xe | K47: Tiền xăng | L47: Tiền xăng | M47: Tiền xăng | N47: 0.2 | P47: ='Từ khóa'!F17 -> Chi tiền điện, nước, internet, điện thoại, xăng xe | T47: ='Kế hoạch thu nhập và chi tiêu'!L31 -> 2 | W47: =SUMIF($G$42:$J$82,P47,$N$42:$N$82) -> 1.65 | X47: =T47-W47 -> 0.35 | Z47: Giá xăng tăng mạnh | AF47: Giảm chi tiêu tháng sau
E48: 44627 | F48: 44599 | G48: Chi tiền điện, nước, internet, điện thoại, xăng xe | H48: Chi tiền điện, nước, internet, điện thoại, xăng xe | I48: Chi tiền điện, nước, internet, điện thoại, xăng xe | J48: Chi tiền điện, nước, internet, điện thoại, xăng xe | K48: Tiền điện thoại | L48: Tiền điện thoại | M48: Tiền điện thoại | N48: 0.05 | P48: ='Từ khóa'!F18 -> Chi tiền giải trí, quà tặng | T48: ='Kế hoạch thu nhập và chi tiêu'!L32 -> 0 | W48: =SUMIF($G$42:$J$82,P48,$N$42:$N$82) -> 0.7 | X48: =T48-W48 -> -0.7 | Z48: Gia hạn gói giải trí thời hạn 3 tháng
E49: 44629 | F49: 44601 | G49: Đi ăn ở ngoài | H49: Đi ăn ở ngoài | I49: Đi ăn ở ngoài | J49: Đi ăn ở ngoài | N49: 0.5 | P49: ='Từ khóa'!F19 -> Chi tiền cho con | T49: ='Kế hoạch thu nhập và chi tiêu'!L33 -> 0 | W49: =SUMIF($G$42:$J$82,P49,$N$42:$N$82) -> 0 | X49: =T49-W49 -> 0
E50: 44631 | F50: 44603 | G50: Chi tiền phát triển bản thân | H50: Chi tiền phát triển bản thân | I50: Chi tiền phát triển bản thân | J50: Chi tiền phát triển bản thân | K50: Mua sách | L50: Mua sách | M50: Mua sách | N50: 0.3 | P50: ='Từ khóa'!F20 -> Chi tiền trả nợ | T50: ='Kế hoạch thu nhập và chi tiêu'!L34 -> 6.5 | W50: =SUMIF($G$42:$J$82,P50,$N$42:$N$82) -> 6.5 | X50: =T50-W50 -> 0
E51: 44632 | F51: 44604 | G51: Chi tiền phát triển bản thân | H51: Chi tiền phát triển bản thân | I51: Chi tiền phát triển bản thân | J51: Chi tiền phát triển bản thân | K51: Khóa học | L51: Khóa học | M51: Khóa học | N51: 0.5 | P51: ='Từ khóa'!F21 -> Chi tiền cho tặng gia đình | T51: ='Kế hoạch thu nhập và chi tiêu'!L35 -> 1 | W51: =SUMIF($G$42:$J$82,P51,$N$42:$N$82) -> 0 | X51: =T51-W51 -> 1
E52: 44640 | F52: 44612 | G52: Chi tiền phát triển bản thân | K52: Khóa học | N52: 0.7 | P52: ='Từ khóa'!F22 -> Chi tiêu 1 | T52: ='Kế hoạch thu nhập và chi tiêu'!L36 -> 0 | W52: =SUMIF($G$42:$J$82,P52,$N$42:$N$82) -> 0 | X52: =T52-W52 -> 0
E53: 44642 | F53: 22/02/2022 | G53: Mua thực phẩm | N53: 0.8 | P53: ='Từ khóa'!F23 -> Chi tiêu 2 | T53: ='Kế hoạch thu nhập và chi tiêu'!L37 -> 0 | W53: =SUMIF($G$42:$J$82,P53,$N$42:$N$82) -> 0 | X53: =T53-W53 -> 0
E54: 44643 | F54: 44615 | G54: Chi tiền bảo hiểm | K54: Bảo hiểm y tế | N54: 0.5 | P54: ='Từ khóa'!F24 -> Chi tiêu 3 | T54: ='Kế hoạch thu nhập và chi tiêu'!L38 -> 0 | W54: =SUMIF($G$42:$J$82,P54,$N$42:$N$82) -> 0 | X54: =T54-W54 -> 0
E55: 44644 | F55: 44616 | G55: Chi tiền điện, nước, internet, điện thoại, xăng xe | K55: Tiền xăng | N55: 0.3 | P55: ='Từ khóa'!F25 -> Chi tiêu 4 | T55: ='Kế hoạch thu nhập và chi tiêu'!L39 -> 0 | W55: =SUMIF($G$42:$J$82,P55,$N$42:$N$82) -> 0 | X55: =T55-W55 -> 0
E56: 44645 | F56: 44617 | G56: Chi tiền giải trí, quà tặng | K56: Sinh nhật | N56: 0.5 | P56: ='Từ khóa'!F26 -> Chi tiêu 5 | T56: ='Kế hoạch thu nhập và chi tiêu'!L40 -> 0 | X56: =T56-W56 -> 0
E57: 44646 | F57: 44618 | G57: Mua đồ dùng trong nhà | N57: 0.7 | P57: Tổng chi tiêu | T57: =SUM(T42:U56) -> 18.5 | V57: =SUM(W42:W56) -> 19.25 | X57: =SUM(X42:Y56) -> -0.75
E58: 44647 | F58: 44619 | G58: Chi tiền trả nợ | N58: 6.5
E59: 44648 | F59: 22/02/2022 | G59: Chi tiền giải trí, quà tặng | K59: Gia hạn gói Nexflix 3 tháng | N59: 0.2
E83: Tổng chi tiêu | N83: =SUM(N42:N82) -> 19.25
E86: Phần 2: Các khoản đầu tư phát triển bản thân chi tiết
...

Sheet T4
E1: THEO DÕI THU - CHI THÁNG 4
L3: Đơn vị: triệu đồng
F4: Phần 1 | G4: Phần 2
E6: Phần 1: Theo dõi thu chi
E9: Tổng thu nhập | I9: =N37 -> 23.9
E14: Tổng chi phí | I14: =N83 -> 17.25
E19: Tiết kiệm | I19: =I9-I14 -> 6.65
E25: Thu nhập chi tiết | P25: Tổng kết thu nhập
E26: Thời gian | G26: Các khoản thu nhập | K26: Mô tả chi tiết | N26: Tổng | P26: Danh mục | T26: Kế hoạch | V26: Thực tế | X26: Chênh lệch | Z26: Lý do | AF26: Biện pháp
E27: 44666 | G27: Lương từ công ty | N27: 19 | P27: ='Từ khóa'!M12 -> Lương từ công ty | T27: ='Kế hoạch thu nhập và chi tiêu'!L11 -> 20 | W27: =SUMIF($G$27:$J$36,P27,$N$27:$N$36) -> 19 | X27: =W27-T27 -> -1
E28: 44671 | F28: 44612 | G28: Thu nhập khác | N28: 4 | P28: ='Từ khóa'!M13 -> Thu nhập khác | T28: ='Kế hoạch thu nhập và chi tiêu'!L12 -> 10 | W28: =SUMIF($G$27:$J$36,P28,$N$27:$N$36) -> 4.9 | X28: =W28-T28 -> -5.1
E29: 44679 | F29: 44620 | G29: Thu nhập khác | N29: 0.3 | P29: ='Từ khóa'!M14 -> 0 | T29: ='Kế hoạch thu nhập và chi tiêu'!L13 -> 0 | W29: =SUMIF($G$27:$J$36,P29,$N$27:$N$36) -> 0 | X29: =W29-T29 -> 0
E30: 44679 | F30: 44620 | G30: Thu nhập khác | N30: 0.6 | P30: ='Từ khóa'!M15 -> 0 | T30: ='Kế hoạch thu nhập và chi tiêu'!L14 -> 0 | W30: =SUMIF($G$27:$J$36,P30,$N$27:$N$36) -> 0 | X30: =W30-T30 -> 0
P31: ='Từ khóa'!M16 -> 0 | T31: ='Kế hoạch thu nhập và chi tiêu'!L15 -> 0 | W31: =SUMIF($G$27:$J$36,P31,$N$27:$N$36) -> 0 | X31: =W31-T31 -> 0
P32: ='Từ khóa'!M17 -> 0 | T32: ='Kế hoạch thu nhập và chi tiêu'!L16 -> 0 | W32: =SUMIF($G$27:$J$36,P32,$N$27:$N$36) -> 0 | X32: =W32-T32 -> 0
P33: ='Từ khóa'!M18 -> 0 | T33: ='Kế hoạch thu nhập và chi tiêu'!L17 -> 0 | W33: =SUMIF($G$27:$J$36,P33,$N$27:$N$36) -> 0 | X33: =W33-T33 -> 0
P34: ='Từ khóa'!M19 -> 0 | T34: ='Kế hoạch thu nhập và chi tiêu'!L18 -> 0 | W34: =SUMIF($G$27:$J$36,P34,$N$27:$N$36) -> 0 | X34: =W34-T34 -> 0
E37: Tổng thu nhập | N37: =SUBTOTAL(109,'T4'!$N$27:$N$36) -> 23.9 | P37: Tổng thu nhập | T37: =SUM(T27:U36) -> 30 | V37: =SUM(W27:W36) -> 23.9 | X37: =SUM(X27:Y36) -> -6.1
